<mujoco model="SO100_Arm">
    <compiler angle="radian" coordinate="local" />

    <option gravity="0 0 -9.81" />

    <default>
        <joint limited="true" damping="1" />
        <geom type="capsule" size="0.02 0.1" rgba="0.4 0.4 0.8 1" />
    </default>

    <worldbody>
        <body name="base" pos="0 0 0">
            <geom type="cylinder" size="0.05 0.02" rgba="0.6 0.6 0.6 1" />

            <!-- Joint 1: Base rotation -->
            <body name="link1" pos="0 0 0.02">
                <joint name="joint1" axis="0 0 1" range="-3.14 3.14" />
                <geom fromto="0 0 0 0 0 0.2" />

                <!-- Joint 2: Shoulder -->
                <body name="link2" pos="0 0 0.2">
                    <joint name="joint2" axis="0 1 0" range="-1.57 1.57" />
                    <geom fromto="0 0 0 0 0 0.2" />

                    <!-- Joint 3: Elbow -->
                    <body name="link3" pos="0 0 0.2">
                        <joint name="joint3" axis="0 1 0" range="-1.57 1.57" />
                        <geom fromto="0 0 0 0 0 0.2" />

                        <!-- Joint 4: Wrist pitch -->
                        <body name="link4" pos="0 0 0.2">
                            <joint name="joint4" axis="0 1 0" range="-1.57 1.57" />
                            <geom fromto="0 0 0 0 0 0.1" />

                            <!-- Joint 5: Wrist roll -->
                            <body name="link5" pos="0 0 0.1">
                                <joint name="joint5" axis="1 0 0" range="-3.14 3.14" />
                                <geom fromto="0 0 0 0 0 0.1" />

                                <!-- Joint 6: End-effector rotate -->
                                <body name="link6" pos="0 0 0.1">
                                    <joint name="joint6" axis="0 0 1" range="-3.14 3.14" />
                                    <geom fromto="0 0 0 0 0 0.1" />
                                </body>
                            </body>
                        </body>
                    </body>
                </body>
            </body>
        </body>
    </worldbody>

    <actuator>
        <position joint="joint1" kp="50"/>
        <position joint="joint2" kp="50"/>
        <position joint="joint3" kp="50"/>
        <position joint="joint4" kp="50"/>
        <position joint="joint5" kp="50"/>
        <position joint="joint6" kp="50"/>
    </actuator>
</mujoco>
